Workbook

Sheet Sheet1
A1: THE REALNESS SCORE
A3: Affect. Self-Consciousness. Attachment. Choice.
A4: Feel it, don’t fake it.
A6: SECTION 1 — QUICK REALNESS CHECK
A8: Instructions:
A9: Rate each statement from 1 to 5.
A10: 1 = Not at all true of me
A11: 5 = Very true of me
B12: CAS-15 Response (1–5)
A13: 1. I can notice emotions in my body.
A14: 2. When I feel uncomfortable, I act okay.
A15: 3. I show excitement naturally when something matters.
A16: 4. I shut down my feelings when I feel exposed.
A17: 5. I can show anger or disappointment without losing control.
A18: 6. I act cheerful so people don’t think I’m difficult.
A19: 7. When I’m hurt, I can ask for help.
A20: 8. I pull away from people before they can reject me.
A21: 9. I enjoy good moments without expecting bad things.
A22: 10. I use humor or confidence to hide real feelings.
A23: 11. When I’m scared, I tell someone.
A24: 12. I explain myself too much when I feel judged.
... A27: 15. I feel like the same person inside and outside.
A28: CAS-15 Total Score | B28: =SUM(B13:B27)
A29: SECTION 2 — FULL REALNESS ASSESSMENT
A31: Instructions:
A32: Rate each statement from 1 to 5.
A33: 1 = Not at all true of me
A34: 5 = Very true of me
A36: A. NOTICING YOUR FEELINGS
A38: How well you notice and handle your feelings.
B39: CAS-40 Response (1–5)
A40: 1. I can notice emotions in my body.
A41: 2. When I feel uncomfortable, I act okay.
A42: 3. I show excitement naturally when something matters.
A43: 4. I shut down my feelings when I feel exposed.
A44: 5. I can show anger or disappointment without losing control.
A45: 6. I act cheerful so people don’t think I’m difficult.
A46: 7. When I’m hurt, I can ask for help.
A47: 8. I pull away from people before they can reject me.
A48: 9. I enjoy good moments without expecting bad things.
...

Sheet Dashboard
A1: REALNESS SCORE DASHBOARD
A3: Quick Realness Check (CAS-15) | B3: =Sheet1!B28
A5: Full Realness Score (CAS-40) | B5: =Sheet1!B96
A7: Subscale A: Noticing Your Feelings | B7: =Sheet1!B50
A9: Subscale B: Showing Your Real Self | B9: =Sheet1!B65
A11: Subscale C: How You Protect Yourself | B11: =Sheet1!B80
A13: Subscale D: How You Connect With Others | B13: =Sheet1!B95
A15: Your Realness Archetype | B15: =Archetypes!H3
A16: Archetype Description | B16: =Archetypes!H4
A17: Most Compatible Archetype | B17: =Archetypes!H5
A18: Challenging Match Archetype | B18: =Archetypes!H6
A19: Image Prompt (for AI art) | B19: =Archetypes!H7

Sheet Definitions
A1: SUBSCALE DEFINITIONS
A3: Noticing Your Feelings | B3: How well you notice and handle your feelings.
A5: Showing Your Real Self | B5: How honestly you express what you feel.
A7: How You Protect Yourself | B7: How you react when you feel watched or judged.
A9: How You Connect With Others | B9: How you usually act in close relationships.

Sheet Printable
A1: THE REALNESS SCORE – PRINTABLE ASSESSMENT
A3: Use this sheet to print a clean version of the assessment.
A5: Rate each statement from 1 to 5. | B5: ______
A7: Rate each statement from 1 to 5. | B7: ______

Sheet Archetypes
A1: REALNESS ARCHETYPES – CLASSIFICATION
A3: Subscale Scores | B3: A – Noticing Your Feelings | C3: B – Showing Your Real Self | D3: C – How You Protect Yourself | E3: D – How You Connect With Others | G3: Best-fit Archetype | H3: =IF($B$5="","",INDEX(B10:B25,MATCH(MIN(L10:L25),L10:L25,0)))
B4: =Sheet1!B50 | C4: =Sheet1!B65 | D4: =Sheet1!B80 | E4: =Sheet1!B95 | G4: Description | H4: =IF($B$5="","",INDEX(H10:H25,MATCH(MIN(L10:L25),L10:L25,0)))
A5: Level (1=Low, 2=Medium, 3=High) | B5: =IF(B4="","",IF(B4<=23,1,IF(B4<=36,2,3))) | C5: =IF(C4="","",IF(C4<=23,1,IF(C4<=36,2,3))) | D5: =IF(D4="","",IF(D4<=23,1,IF(D4<=36,2,3))) | E5: =IF(E4="","",IF(E4<=23,1,IF(E4<=36,2,3))) | G5: Most Compatible With | H5: =IF($B$5="","",INDEX(I10:I25,MATCH(MIN(L10:L25),L10:L25,0)))
G6: Challenging Match | H6: =IF($B$5="","",INDEX(J10:J25,MATCH(MIN(L10:L25),L10:L25,0)))
G7: Image Prompt | H7: =IF($B$5="","",INDEX(K10:K25,MATCH(MIN(L10:L25),L10:L25,0)))
A9: ID | B9: Archetype Name | C9: Short Tag | D9: A Level | E9: B Level | F9: C Level | G9: D Level | H9: One-line Description | I9: Most Compatible | J9: Least Compatible | K9: Visual Prompt | L9: Distance
A10: 1 | B10: The Resonant Sage | C10: Wise Regulator | D10: 3 | E10: 3 | F10: 1 | G10: 3 | H10: Deep-feeling, steady, and emotionally grounded. | I10: The Soft Anchor | J10: The Iron Mask | K10: A calm guardian carved from shadowed stone, soft light glowing inside their chest, standing alone in a field at dusk, realistic, dark muted palette, subtle inner glow, highly detailed. | L10: =IF($B$5="","",ABS(D10-$B$5)+ABS(E10-$C$5)+ABS(F10-$D$5)+ABS(G10-$E$5))
A11: 2 | B11: The Soft Anchor | C11: Warm Stabilizer | D11: 3 | E11: 2 | F11: 1 | G11: 3 | H11: Gentle, steady, and nurturing in relationships. | I11: The Resonant Sage | J11: The Stormbound | K11: A figure sitting on a weathered pier over dark water at sunset, soft light around them, posture relaxed and inviting, semi-realistic, moody but warm atmosphere. | L11: =IF($B$5="","",ABS(D11-$B$5)+ABS(E11-$C$5)+ABS(F11-$D$5)+ABS(G11-$E$5))
A12: 3 | B12: The Stormbound | C12: Hidden Storm | D12: 3 | E12: 1 | F12: 3 | G12: 1 | H12: Feels intensely inside but stays guarded and overwhelmed. | I12: The Truth Teller | J12: The Soft Anchor | K12: A person made of swirling storm clouds, faint lightning under the skin, seated in a dim room, shafts of light from a single window, cinematic realism, dramatic shadows. | L12: =IF($B$5="","",ABS(D12-$B$5)+ABS(E12-$C$5)+ABS(F12-$D$5)+ABS(G12-$E$5))
A13: 4 | B13: The Truth Teller | C13: Blunt Realist | D13: 3 | E13: 3 | F13: 2 | G13: 1 | H13: Emotionally aware and radically honest, sometimes too sharp. | I13: The Stormbound | J13: The Gentle Ghost | K13: A figure speaking into the dark, words forming visible glowing lines in the air, sharp edges of light, high contrast, realistic style with a slightly surreal twist. | L13: =IF($B$5="","",ABS(D13-$B$5)+ABS(E13-$C$5)+ABS(F13-$D$5)+ABS(G13-$E$5))
A14: 5 | B14: The Open Flame | C14: Impulsive Feeler | D14: 2 | E14: 3 | F14: 1 | G14: 2 | H14: Expressive and passionate, quick to feel and show emotions. | I14: The Inner Compass | J14: The Fortress-Keeper | K14: A person surrounded by small floating sparks in a dark room, eyes bright, mid-motion as if laughing or talking, warm highlights against deep shadow, expressive realism. | L14: =IF($B$5="","",ABS(D14-$B$5)+ABS(E14-$C$5)+ABS(F14-$D$5)+ABS(G14-$E$5))
A15: 6 | B15: The Magnetic Poet | C15: Soul Storyteller | D15: 3 | E15: 3 | F15: 2 | G15: 3 | H15: Emotionally articulate, romantic, and deeply sensitive. | I15: The Quiet Depth | J15: The Mirror Mask | K15: A lone figure writing at a desk lit by a single lamp, pages drifting into faint glowing symbols, dark room, rich shadows, painterly realistic style. | L15: =IF($B$5="","",ABS(D15-$B$5)+ABS(E15-$C$5)+ABS(F15-$D$5)+ABS(G15-$E$5))
A16: 7 | B16: The Mirror Mask | C16: Social Chameleon | D16: 2 | E16: 3 | F16: 3 | G16: 2 | H16: Reads the room fast and adjusts their emotional display. | I16: The Quiet Depth | J16: The Magnetic Poet | K16: A person holding a half-mirror mask, one eye visible and observant, reflections of other faces in the mask surface, cool tones, realistic with subtle surreal reflections. | L16: =IF($B$5="","",ABS(D16-$B$5)+ABS(E16-$C$5)+ABS(F16-$D$5)+ABS(G16-$E$5))
A17: 8 | B17: The Boundary Breaker | C17: Radical Sharer | D17: 2 | E17: 3 | F17: 1 | G17: 3 | H17: Open, intense, and quick to share deeply and directly. | I17: The Fortress-Keeper | J17: The Stormbound | K17: Two figures facing each other in a dark space, one pouring glowing light from their chest toward the other, bold and intimate, realistic style, strong contrast. | L17: =IF($B$5="","",ABS(D17-$B$5)+ABS(E17-$C$5)+ABS(F17-$D$5)+ABS(G17-$E$5))
A18: 9 | B18: The Iron Mask | C18: Locked Down | D18: 1 | E18: 1 | F18: 3 | G18: 1 | H18: Emotionally shut down, highly self-protective, hard to read. | I18: The Boundary Breaker | J18: The Resonant Sage | K18: A figure in a smooth dark metal mask, eyes hidden, standing against a black background, faint cracks with tiny light leaking through, hyperreal texture. | L18: =IF($B$5="","",ABS(D18-$B$5)+ABS(E18-$C$5)+ABS(F18-$D$5)+ABS(G18-$E$5))
A19: 10 | B19: The Strategist | C19: Controlled Planner | D19: 2 | E19: 2 | F19: 3 | G19: 1 | H19: Thinks before feeling, manages emotions through logic. | I19: The Open Flame | J19: The Boundary Breaker | K19: A person at a table covered in maps and diagrams lit from above, expression calm and focused, everything else fading into darkness, realistic, clean lines. | L19: =IF($B$5="","",ABS(D19-$B$5)+ABS(E19-$C$5)+ABS(F19-$D$5)+ABS(G19-$E$5))
A20: 11 | B20: The Gentle Ghost | C20: Quiet Withdrawer | D20: 1 | E20: 1 | F20: 3 | G20: 2 | H20: Pulls back softly when overwhelmed, avoids conflict. | I20: The Magnetic Poet | J20: The Truth Teller | K20: A faint, semi-transparent figure walking down a dim hallway, edges blurred into the shadows, soft cool tones, melancholic but peaceful realism. | L20: =IF($B$5="","",ABS(D20-$B$5)+ABS(E20-$C$5)+ABS(F20-$D$5)+ABS(G20-$E$5))
A21: 12 | B21: The Fortress-Keeper | C21: Guarded Loyalist | D21: 2 | E21: 1 | F21: 3 | G21: 3 | H21: Slow to trust but fiercely loyal once you are inside. | I21: The Boundary Breaker | J21: The Open Flame | K21: A tall stone gate in the night with a single warm light deep inside, heavy doors slightly open, realistic stone texture, moody sky above. | L21: =IF($B$5="","",ABS(D21-$B$5)+ABS(E21-$C$5)+ABS(F21-$D$5)+ABS(G21-$E$5))
... A25: 16 | B25: The Inner Compass | C25: Centered Guide | D25: 2 | E25: 2 | F25: 2 | G25: 3 | H25: Balanced between independence and closeness, steady and clear. | I25: The Open Flame | J25: The Gentle Ghost | K25: A figure standing in a dark space with a softly glowing compass in their hands, light illuminating their face, calm expression, grounded, hyperreal detail. | L25: =IF($B$5="","",ABS(D25-$B$5)+ABS(E25-$C$5)+ABS(F25-$D$5)+ABS(G25-$E$5))
